2024-03-07 15:59:58,362 INFO    StreamThr :20216 [internal.py:wandb_internal():86] W&B internal server running at pid: 20216, started at: 2024-03-07 15:59:58.361109
2024-03-07 15:59:58,363 DEBUG   HandlerThread:20216 [handler.py:handle_request():146] handle_request: status
2024-03-07 15:59:58,632 INFO    WriterThread:20216 [datastore.py:open_for_write():87] open: C:\Users\arcot\OneDrive\Desktop\MRM-TaskPhase\wandb\run-20240307_155958-swyg6beh\run-swyg6beh.wandb
2024-03-07 15:59:58,633 DEBUG   SenderThread:20216 [sender.py:send():378] send: header
2024-03-07 15:59:58,670 DEBUG   SenderThread:20216 [sender.py:send():378] send: run
2024-03-07 15:59:59,330 ERROR   SenderThread:20216 [internal_api.py:execute():373] 404 response executing GraphQL.
2024-03-07 15:59:59,330 ERROR   SenderThread:20216 [internal_api.py:execute():374] {"errors":[{"message":"entity entity_name not found during upsertBucket","path":["upsertBucket"]}],"data":{"upsertBucket":null}}
2024-03-07 15:59:59,335 ERROR   SenderThread:20216 [sender.py:send_run():950] It appears that you do not have permission to access the requested resource. Please reach out to the project owner to grant you access. If you have the correct permissions, verify that there are no issues with your networking setup.(Error 404: Not Found)
Traceback (most recent call last):
  File "C:\Users\arcot\AppData\Local\Programs\Python\Python311\Lib\site-packages\wandb\sdk\lib\retry.py", line 131, in __call__
    result = self._call_fn(*args, **kwargs)
             ^^^^^^^^^^^^^^^^^^^^^^^^^^^^^^
  File "C:\Users\arcot\AppData\Local\Programs\Python\Python311\Lib\site-packages\wandb\sdk\internal\internal_api.py", line 369, in execute
    return self.client.execute(*args, **kwargs)  # type: ignore
           ^^^^^^^^^^^^^^^^^^^^^^^^^^^^^^^^^^^^
  File "C:\Users\arcot\AppData\Local\Programs\Python\Python311\Lib\site-packages\wandb\vendor\gql-0.2.0\wandb_gql\client.py", line 52, in execute
    result = self._get_result(document, *args, **kwargs)
             ^^^^^^^^^^^^^^^^^^^^^^^^^^^^^^^^^^^^^^^^^^^
  File "C:\Users\arcot\AppData\Local\Programs\Python\Python311\Lib\site-packages\wandb\vendor\gql-0.2.0\wandb_gql\client.py", line 60, in _get_result
    return self.transport.execute(document, *args, **kwargs)
           ^^^^^^^^^^^^^^^^^^^^^^^^^^^^^^^^^^^^^^^^^^^^^^^^^
  File "C:\Users\arcot\AppData\Local\Programs\Python\Python311\Lib\site-packages\wandb\sdk\lib\gql_request.py", line 59, in execute
    request.raise_for_status()
  File "C:\Users\arcot\AppData\Local\Programs\Python\Python311\Lib\site-packages\requests\models.py", line 1021, in raise_for_status
    raise HTTPError(http_error_msg, response=self)
requests.exceptions.HTTPError: 404 Client Error: Not Found for url: https://api.wandb.ai/graphql

During handling of the above exception, another exception occurred:

Traceback (most recent call last):
  File "C:\Users\arcot\AppData\Local\Programs\Python\Python311\Lib\site-packages\wandb\sdk\internal\sender.py", line 948, in send_run
    self._init_run(run, config_value_dict)
  File "C:\Users\arcot\AppData\Local\Programs\Python\Python311\Lib\site-packages\wandb\sdk\internal\sender.py", line 990, in _init_run
    server_run, inserted, server_messages = self._api.upsert_run(
                                            ^^^^^^^^^^^^^^^^^^^^^
  File "C:\Users\arcot\AppData\Local\Programs\Python\Python311\Lib\site-packages\wandb\apis\normalize.py", line 73, in wrapper
    raise err
  File "C:\Users\arcot\AppData\Local\Programs\Python\Python311\Lib\site-packages\wandb\apis\normalize.py", line 41, in wrapper
    return func(*args, **kwargs)
           ^^^^^^^^^^^^^^^^^^^^^
  File "C:\Users\arcot\AppData\Local\Programs\Python\Python311\Lib\site-packages\wandb\sdk\internal\internal_api.py", line 2216, in upsert_run
    response = self.gql(
               ^^^^^^^^^
  File "C:\Users\arcot\AppData\Local\Programs\Python\Python311\Lib\site-packages\wandb\sdk\internal\internal_api.py", line 341, in gql
    ret = self._retry_gql(
          ^^^^^^^^^^^^^^^^
  File "C:\Users\arcot\AppData\Local\Programs\Python\Python311\Lib\site-packages\wandb\sdk\lib\retry.py", line 147, in __call__
    retry_timedelta_triggered = check_retry_fn(e)
                                ^^^^^^^^^^^^^^^^^
  File "C:\Users\arcot\AppData\Local\Programs\Python\Python311\Lib\site-packages\wandb\util.py", line 968, in check_retry_fn
    return fallback_retry_fn(e)
           ^^^^^^^^^^^^^^^^^^^^
  File "C:\Users\arcot\AppData\Local\Programs\Python\Python311\Lib\site-packages\wandb\util.py", line 910, in no_retry_auth
    raise CommError(
wandb.errors.CommError: It appears that you do not have permission to access the requested resource. Please reach out to the project owner to grant you access. If you have the correct permissions, verify that there are no issues with your networking setup.(Error 404: Not Found)
2024-03-07 15:59:59,574 DEBUG   HandlerThread:20216 [handler.py:handle_request():146] handle_request: shutdown
2024-03-07 15:59:59,574 INFO    HandlerThread:20216 [handler.py:finish():869] shutting down handler
2024-03-07 15:59:59,671 INFO    WriterThread:20216 [datastore.py:close():296] close: C:\Users\arcot\OneDrive\Desktop\MRM-TaskPhase\wandb\run-20240307_155958-swyg6beh\run-swyg6beh.wandb
2024-03-07 16:00:00,352 INFO    SenderThread:20216 [sender.py:finish():1521] shutting down sender
